## Promise对象

### 含义

特点

 - 对象的状态不受外界影响。Promise对象代表一个异步操作，有三种状态：Pending（进行中）、Resolved（已完成，又称Fulfilled）和Rejected（已失败）。
 - 一旦状态改变，就不会再变，任何时候都可以得到这个结果。Promise对象的状态改变，只有两种可能：从Pending变为Resolved和从Pending变为Rejected
 
 缺点
 
 - 首先，无法取消Promise，一旦新建它就会立即执行，无法中途取消。
 - 其次，如果不设置回调函数，Promise内部抛出的错误，不会反应到外部。
 - 第三，当处于Pending状态时，无法得知目前进展到哪一个阶段（刚刚开始还是即将完成）。
 
 
 ### 基本用法
 
 ```
 // resolve,reject自带
 var promise = new Promise(function(resolve, reject) {
  // ... some code

  if (/* 异步操作成功 */){
    resolve(value);
  } else {
    reject(error);
  }
});

// 生成实例后
promise.then(function(value) {
  // success
}, function(value) {
  // failure
});
// 第二个可选
```

```
function timeout(ms) {
  return new Promise((resolve, reject) => {
    setTimeout(resolve, ms, 'done');
  });
}

timeout(100).then((value) => {
  console.log(value);
});

// 异步加载图片
function loadImageAsync(url) {
  return new Promise(function(resolve, reject) {
    var image = new Image();

    image.onload = function() {
      resolve(image);
    };

    image.onerror = function() {
      reject(new Error('Could not load image at ' + url));
    };

    image.src = url;
  });
}
```

```
// 实现的Ajax操作
var getJSON = function(url) {
  var promise = new Promise(function(resolve, reject){
    var client = new XMLHttpRequest();
    client.open("GET", url);
    client.onreadystatechange = handler;
    client.responseType = "json";
    client.setRequestHeader("Accept", "application/json");
    client.send();

    function handler() {
      if ( this.readyState !== 4 ) {
        return;
      }
      if (this.status === 200) {
        resolve(this.response);
      } else {
        reject(new Error(this.statusText));
      }
    };
  });

  return promise;
};

getJSON("/posts.json").then(function(json) {
  console.log('Contents: ' + json);
}, function(error) {
  console.error('出错了', error);
});
```

```
// p1是一个Promise，3秒之后变为rejected。p2的状态由p1决定，1秒之后，
// p2调用resolve方法，但是此时p1的状态还没有改变，因此p2的状态也不会变。
// 又过了2秒，p1变为rejected，p2也跟着变为rejected。
var p1 = new Promise(function (resolve, reject) {
  setTimeout(() => reject(new Error('fail')), 3000)
})
var p2 = new Promise(function (resolve, reject) {
  setTimeout(() => resolve(p1), 1000)
})
p2.then(result => console.log(result))
p2.catch(error => console.log(error))
// Error: fail
```



###     Promise.prototype.then()

then方法返回的是一个新的Promise实例（注意，不是原来那个Promise实例）


```
getJSON("/post/1.json").then(function(post) {
  return getJSON(post.commentURL);
}).then(function funcA(comments) {
  console.log("Resolved: ", comments);
}, function funcB(err){
  console.log("Rejected: ", err);
});

// 剪头函数

getJSON("/post/1.json").then(
  post => getJSON(post.commentURL)
).then(
  comments => console.log("Resolved: ", comments),
  err => console.log("Rejected: ", err)
);
```

### Promise.prototype.catch()


Promise.prototype.catch方法是.then(null, rejection)的别名，用于指定发生错误时的回调函数

```
p.then((val) => console.log("fulfilled:", val))
  .catch((err) => console.log("rejected:", err));

// 等同于

p.then((val) => console.log(fulfilled:", val))
  .then(null, (err) => console.log("rejected:", err));
  ```
  
  
  ```
  // bad
promise
  .then(function(data) {
    // success
  }, function(err) {
    // error
  });

// good
promise
  .then(function(data) { //cb
    // success
  })
  .catch(function(err) {
    // error
  });
// 前者更接近同步的写法（try/catch）
  ```
  
  ```
  var someAsyncThing = function() {
  return new Promise(function(resolve, reject) {
    // 下面一行会报错，因为x没有声明
    resolve(x + 2);
  });
};

someAsyncThing()
.catch(function(error) {
  console.log('oh no', error);
})
.then(function() {
  console.log('carry on');
});
// oh no [ReferenceError: x is not defined]
// carry on
// catch方法返回的还是一个Promise对象，因此后面还可以接着调用then方法
```

```
// catch还能捕获catch中的错误
someAsyncThing().then(function() {
  return someOtherAsyncThing();
}).catch(function(error) {
  console.log('oh no', error);
  // 下面一行会报错，因为y没有声明
  y + 2;
}).catch(function(error) {
  console.log('carry on', error);
});
// oh no [ReferenceError: x is not defined]
// carry on [ReferenceError: y is not defined]
```


### Promise.all()

Promise.all方法的参数不一定是数组，但是必须具有iterator接口，且返回的每个成员都是Promise实例。
必须全部fulfilled，这个组合实例才能fulfilled；

```
// 生成一个Promise对象的数组
var promises = [2, 3, 5, 7, 11, 13].map(function(id){
  return getJSON("/post/" + id + ".json");
});

Promise.all(promises).then(function(posts) {
  // ...
}).catch(function(reason){
  // ...
});
```


### Promise.race()

只要谁先fulfilled，这个组合实例就可fulfilled
```
var p = Promise.race([
  fetch('/resource-that-may-take-a-while'),
  new Promise(function (resolve, reject) {
    setTimeout(() => reject(new Error('request timeout')), 5000)
  })
])
p.then(response => console.log(response))
p.catch(error => console.log(error))
// 如果5秒之内fetch方法无法返回结果，变量p的状态就会变为rejected，
// 从而触发catch方法指定的回调函数。
```


### Promise.resolve()

```
Promise.resolve('foo')
// 等价于
new Promise(resolve => resolve('foo'))
```

如果Promise.resolve方法的参数，不是具有then方法的对象（又称thenable对象），则返回一个新的Promise对象，且它的状态为Resolved。

```
var p = Promise.resolve('Hello');

p.then(function (s){
  console.log(s)
});
// Hello
```

```
// 可不带参数，直接得到一个Promise对象
var p = Promise.resolve();

p.then(function () {
  // ...
});
```

### Promise.reject()


```
var p = Promise.reject('出错了');
// 等同于
var p = new Promise((resolve, reject) => reject('foo'))

p.then(null, function (s){
  console.log(s)
});
// 出错了
```

### 两个有用的附加方法

 - done()

提供一个done方法，总是处于回调链的尾端，保证抛出任何可能出现的错误

```
asyncFunc()
  .then(f1)
  .catch(r1)
  .then(f2)
  .done();
  
Promise.prototype.done = function (onFulfilled, onRejected) {
  this.then(onFulfilled, onRejected)
    .catch(function (reason) {
      // 抛出一个全局错误
      setTimeout(() => { throw reason }, 0);
    });
};
```

 - finally()
 
 ```
 server.listen(0)
  .then(function () {
    // run test
  })
  .finally(server.stop);
  
  Promise.prototype.finally = function (callback) {
  let P = this.constructor;
  return this.then(
    value  => P.resolve(callback()).then(() => value),
    reason => P.resolve(callback()).then(() => { throw reason })
  );
};
// 不管前面的Promise是fulfilled还是rejected，都会执行回调函数callback
  ```

### 应用

 - 加载图片
 
```
const preloadImage = function (path) {
  return new Promise(function (resolve, reject) {
    var image = new Image();
    image.onload  = resolve;
    image.onerror = reject;
    image.src = path;
  });
};
```

 - Generator函数与Promise的结合
 
 ```
 function getFoo () {
  return new Promise(function (resolve, reject){
    resolve('foo');
  });
}

var g = function* () {
  try {
    var foo = yield getFoo();
    console.log(foo);
  } catch (e) {
    console.log(e);
  }
};

function run (generator) {
  var it = generator();

  function go(result) {
    if (result.done) return result.value;

    return result.value.then(function (value) {
      return go(it.next(value));
    }, function (error) {
      return go(it.throw(error));
    });
  }

  go(it.next());
}

run(g);
```
上面代码的Generator函数g之中，有一个异步操作getFoo，它返回的就是一个Promise对象。函数run用来处理这个Promise对象，并调用下一个next方法。








